Workbook

Sheet Cover Page 
D4: Austin Laz
B5: Financial Model
B23: Financial Modeler
B24: Gansari Williams Bioyari

Sheet Model Guide
B4: AUSTIN LAZ
C7: Model Guide
C9: General Information
C10: This section contains information about Austin Laz Plc
D12: Company Information
D13: Company Name | I13: Austin Laz
D14: Company Sector | I14: Industrial Goods
D15: Purpose of Model | I15: Equity Research
D18: Model Information
D19: Model Owner | I19: Elite Ways
D20: Currency | I20: ₦
D21: Model Name | I21: Gansari Williams Bioyari
C24: Model Structure and Navigation
C25: This section contains the model timing and structure
D27: Model Timing
D28: Beginning Historical Period | I28: 43830
D29: Ending Historical Period | I29: 45291
D30: Forcast Year | I30: 5 years
D31: Months in the period | I31: 12
D32: Last Historical Year | I32: 2023
D33: Last Forcast Year | I33: 2028
D35: Model Structure
D36: Cover Page
D37: Model Guide
D38: Historical Data
D39: Assumptions and Drivers
D40: Income Statement
D41: Balance Sheet
D42: Cashflow Statement
D43: Charts and Graphs
D44: Financial Analysis
D45: Valuation

Sheet Historical Data
Q3: MODEL GUIDE
C5: Austin Laz
C6: Start Date | I6: 43466 | J6: 43831 | K6: 44197 | L6: 44562 | M6: 44927 | N6: 45292 | O6: 45658 | P6: 46023 | Q6: 46388 | R6: 46753
C7: End Date | H7: 43465 | I7: 43830 | J7: 44196 | K7: 44561 | L7: 44926 | M7: 45291 | N7: 45657 | O7: 46022 | P7: 46387 | Q7: 46752 | R7: 47118
C8: Years | I8: 2019 | J8: 2020 | K8: 2021 | L8: 2022 | M8: 2023 | N8: 2023 | O8: 2024 | P8: 2025 | Q8: 2026 | R8: 2027
C9: Number of Days | I9: 364 | J9: 364 | K9: 364 | L9: 364 | M9: 364 | N9: 364 | O9: 364 | P9: 364 | Q9: 364 | R9: 364
C14: Description | H14: Unit
C16: INCOME STATEMENT | I16: N'000 | J16: N'000 | K16: N'000 | L16: N'000 | M16: N'000 | N16: N'000 | O16: N'000 | P16: N'000 | Q16: N'000 | R16: N'000
C18: Revenue | I18: 205757 | J18: 0 | K18: 0 | L18: 0 | M18: 0
C19: Cost of Sales | I19: -236482 | J19: 0 | K19: 0 | L19: 0 | M19: 0
C20: Gross Profit/(Loss) | I20: -30725 | J20: 0 | K20: 0 | L20: 0 | M20: 0
C22: Administration Expenses | I22: -42588 | J22: -142139 | K22: -44568 | L22: -44568 | M22: -44568
C23: Distribution Expenses | I23: -4533 | J23: 0 | K23: 0 | L23: 0 | M23: 0
C24: Finance Cost | I24: -6371 | J24: 0 | K24: 0 | L24: 0 | M24: 0
C25: Profit before Tax | I25: -84217 | J25: -142139 | K25: -44568 | L25: -44568 | M25: -44568
C26: Tax Provision | I26: -151 | J26: 0 | K26: 0 | L26: 0 | M26: 0
C27: Profit after Tax | I27: -84368 | J27: -142139 | K27: -44568 | L27: -44568 | M27: -44568
C29: DISCONTINUED OPERATION
C30: Gain/(Loss) on discontinued operation net of tax | I30: 0 | J30: 0 | K30: 0 | L30: 0 | M30: 0
C31: Net Profit for the Period | I31: -84368 | J31: -142139 | K31: -44568 | L31: -44568 | M31: -44568
C33: OTHER COMPREHENSIVE INCOME NET OF TAX | I33: 0 | J33: 0 | K33: 0 | L33: 0 | M33: 0
C34: Total Comprehensive income for the Period | I34: -84368 | J34: -142139 | K34: -44568 | L34: -44568 | M34: -44568
C36: Earning Per Share | I36: -0.08 | J36: -0.13 | K36: -0.04 | L36: -0.04 | M36: -0.04
C37: Diluted Earning per Share | I37: -0.08 | J37: 0 | K37: 0 | L37: 0 | M37: 0
C39: Depreciation &Ammortization | I39: 192314 | J39: 142139 | K39: 44568 | L39: 44568 | M39: 0
C40: Dvidend paid | I40: 0 | J40: 0 | K40: 0 | L40: 0 | M40: 0
C43: STATEMENT OF FINANCIAL POSTION
C46: ASSETS | I46: N'000 | J46: N'000 | K46: N'000 | L46: N'000 | M46: N'000 | N46: N'000 | O46: N'000 | P46: N'000 | Q46: N'000 | R46: N'000
C47: Non Current Assets
C48: Property, Plant & Equipment | I48: 1332870 | J48: 1190731 | K48: 1146163 | L48: 1101595 | M48: 1101595
C49: Intangibles | I49: 151835 | J49: 151835 | K49: 151835 | L49: 151835 | M49: 151835
I50: 1484705 | J50: 1342566 | K50: 1297998 | L50: 1253430 | M50: 1253430
C51: CURRENT ASSETS
C52: Inventories | I52: 25830 | J52: 25830 | K52: 25830 | L52: 25830 | M52: 25830
C53: Trade receivables | I53: 22261 | J53: 22261 | K53: 22261 | L53: 22261 | M53: 22261
C54: Cash and Cash Equivalent | I54: 1057 | J54: 1057 | K54: 1057 | L54: 1057 | M54: 1057
I55: 49148 | J55: 49148 | K55: 49148 | L55: 49148 | M55: 49148
C56: Total Assets | I56: 1533853 | J56: 1391714 | K56: 1347146 | L56: 1302578 | M56: 1302578
C57: EQUITY AND LIABILITIES:
C58: EQUITY
...

Sheet Assumptions and Drivers
Q2: MODEL GUIDE
C4: Austin Laz
C5: Start Date | I5: 43466 | J5: 43831 | K5: 44197 | L5: 44562 | M5: 44927 | N5: 45292 | O5: 45658 | P5: 46023 | Q5: 46388 | R5: 46753
C6: End Date | H6: 43465 | I6: 43830 | J6: 44196 | K6: 44561 | L6: 44926 | M6: 45291 | N6: 45657 | O6: 46022 | P6: 46387 | Q6: 46752 | R6: 47118
C7: Years | I7: 2019 | J7: 2020 | K7: 2021 | L7: 2022 | M7: 2023 | N7: 2023 | O7: 2024 | P7: 2025 | Q7: 2026 | R7: 2027
C8: Number of Days | I8: 364 | J8: 364 | K8: 364 | L8: 364 | M8: 364 | N8: 364 | O8: 364 | P8: 364 | Q8: 364 | R8: 364
C13: Description | G13: Unit
C15: Income Statement
C16: Revenue | G16: [y-o-y Growth] | I16: 0 | J16: =IS!J17/IS!I17-1 -> -1 | K16: =IF(A2=0,0,(B2-A2)/A2) -> 0 | L16: =IF(B2=0,0,(C2-B2)/B2) -> 0 | M16: =IF(C2=0,0,(D2-C2)/C2) -> 0 | N16: 0 | O16: 0 | P16: 0 | Q16: 0 | R16: 0
C17: Cost of Sales | G17: [% of Revenue] | I17: =-(IS!I18/IS!I17) -> 1.1493266 | J17: =IF(A2=0,0,(B2-A2)/A2) -> 0 | K17: =IF(B2=0,0,(C2-B2)/B2) -> 0 | L17: =IF(C2=0,0,(D2-C2)/C2) -> 0 | M17: =IF(D2=0,0,(E2-D2)/D2) -> 0 | N17: 0 | O17: 0 | P17: 0 | Q17: 0 | R17: 0
C18: SG&A | G18: [% of Revenue] | I18: =-(IS!I21/IS!I17) -> 0.22901286 | J18: 0 | K18: =IF(B3=0,0,(C3-B3)/B3) -> 0 | L18: =IF(C3=0,0,(D3-C3)/C3) -> 0 | M18: =IF(D3=0,0,(E3-D3)/D3) -> 0 | N18: 0 | O18: 0 | P18: 0 | Q18: 0 | R18: 0
C19: Depreciation & Ammortization | G19: [% of PPE] | I19: =IS!I24/SOFP!I27 -> 0.14428564 | J19: =IS!J24/SOFP!J27 -> 0.11937121 | K19: =IS!K24/SOFP!K27 -> 0.038884522 | L19: =IS!L24/SOFP!L27 -> 0.0404577 | M19: =IS!M24/SOFP!M27 -> 0 | N19: 0 | O19: =AVERAGE(M19:N19) -> 0 | P19: =AVERAGE(K19:L19) -> 0.039671111 | Q19: =AVERAGE(J19:R19) -> 0.040516789 | R19: =AVERAGE(I19:L19) -> 0.085749768
C20: Finance cost-net | G20: [% of Debt] | I20: =-IS!I27/(SOFP!I39) -> 0.14939968 | J20: =-IS!J27/(SOFP!J39) -> 0 | K20: =-IS!K27/(SOFP!K39) -> 0 | L20: =-IS!L27/(SOFP!L39) -> 0 | M20: =-IS!M27/(SOFP!M39) -> 0 | N20: 0 | O20: 0 | P20: 0 | Q20: 0 | R20: 0
C21: Tax Expenses | G21: [% of EBT] | I21: =IS!I30/IS!I28 -> 0.0017929872 | J21: =IS!J30/IS!J28 -> 0 | K21: =IS!K30/IS!K28 -> 0 | L21: =IS!L30/IS!L28 -> 0 | M21: =IS!M30/IS!M28 -> 0 | N21: 0 | O21: 0 | P21: 0 | Q21: 0 | R21: 0
C27: Statement of Financial Position
C28: Inventories | G28: [average of yrs] | I28: 25830 | J28: 25831 | K28: 25832 | L28: 25833 | M28: 25834 | N28: =AVERAGE(I28:M28) -> 25832 | O28: =AVERAGE(J28:N28) -> 25832.4 | P28: =AVERAGE(K28:O28) -> 25832.68 | Q28: =AVERAGE(L28:P28) -> 25832.816 | R28: =AVERAGE(M28:Q28) -> 25832.779
C29: Trade receivables | G29: [average of yrs] | I29: =SOFP!I23 -> 22261 | J29: =SOFP!J23 -> 22261 | K29: =SOFP!K23 -> 22261 | L29: =SOFP!L23 -> 22261 | M29: =SOFP!M23 -> 22261 | N29: =AVERAGE(I29:M29) -> 22261 | O29: =AVERAGE(J29:N29) -> 22261 | P29: =AVERAGE(K29:O29) -> 22261 | Q29: =AVERAGE(L29:P29) -> 22261 | R29: =AVERAGE(M29:Q29) -> 22261
C31: PPE | G31: [ending balance] | I31: =SOFP!I27 -> 1332870 | J31: =SOFP!J27 -> 1190731 | K31: =SOFP!K27 -> 1146163 | L31: =SOFP!L27 -> 1101595 | M31: =SOFP!M27 -> 1101595 | N31: =N59 -> 1101595 | O31: =O59 -> 1101595 | P31: =P59 -> 1188998 | Q31: =Q59 -> 1101595 | R31: =R59 -> 1101595
C32: Intangible | G32: [ending balance] | I32: =SOFP!I28 -> 151835 | J32: =SOFP!J28 -> 151835 | K32: =SOFP!K28 -> 151835 | L32: =SOFP!L28 -> 151835 | M32: =SOFP!M28 -> 151835 | N32: =$M32 -> 151835 | O32: =$M32 -> 151835 | P32: =$M32 -> 151835 | Q32: =$M32 -> 151835 | R32: =$M32 -> 151835
C34: Trade payables | G34: [Average of Years] | I34: =SOFP!I34 -> 1857 | J34: =SOFP!J34 -> 1857 | K34: =SOFP!K34 -> 1857 | L34: =SOFP!L34 -> 1857 | M34: =SOFP!M34 -> 1857 | N34: =AVERAGE(I34:M34) -> 1857 | O34: =AVERAGE(J34:N34) -> 1857 | P34: =AVERAGE(K34:O34) -> 1857 | Q34: =AVERAGE(L34:P34) -> 1857 | R34: =AVERAGE(M34:Q34) -> 1857
C35: Other payables | G35: [Average of Years] | I35: =SOFP!I35 -> 4971 | J35: =SOFP!J35 -> 4971 | K35: =SOFP!K35 -> 4971 | L35: =SOFP!L35 -> 4971 | M35: =SOFP!M35 -> 4971 | N35: =AVERAGE(I35:M35) -> 4971 | O35: =AVERAGE(J35:N35) -> 4971 | P35: =AVERAGE(K35:O35) -> 4971 | Q35: =AVERAGE(L35:P35) -> 4971 | R35: =AVERAGE(M35:Q35) -> 4971
C37: Long term borrowing | G37: [Ending Balance] | I37: =SOFP!I39 -> 42644 | J37: =SOFP!J39 -> 42644 | K37: =SOFP!K39 -> 42644 | L37: =SOFP!L39 -> 42644 | M37: =SOFP!M39 -> 42644 | N37: =M37 -> 42644 | O37: =N37 -> 42644 | P37: =O37 -> 42644 | Q37: =P37 -> 42644 | R37: =Q37 -> 42644
C39: Paid up share capital | G39: [Ending Balance] | I39: =SOFP!I44 -> 539930 | J39: =SOFP!J44 -> 539930 | K39: =SOFP!K44 -> 539930 | L39: =SOFP!L44 -> 539930 | M39: =SOFP!M44 -> 539930 | N39: =M39 -> 539930 | O39: =N39 -> 539930 | P39: =O39 -> 539930 | Q39: =P39 -> 539930 | R39: =Q39 -> 539930
C40: Capital Reserves | G40: [Ending Balance] | I40: =SOFP!I45 -> 1224776 | J40: =SOFP!J45 -> 1224776 | K40: =SOFP!K45 -> 1224776 | L40: =SOFP!L45 -> 1224776 | M40: =SOFP!M45 -> 1224776 | N40: =M40 -> 1224776 | O40: =N40 -> 1224776 | P40: =O40 -> 1224776 | Q40: =P40 -> 1224776 | R40: =Q40 -> 1224776
C41: Retained Earnings | I41: ='Historical Data'!I61 -> -280325 | J41: ='Historical Data'!J61 -> -422464 | K41: ='Historical Data'!K61 -> -467032 | L41: ='Historical Data'!L61 -> -511600 | M41: ='Historical Data'!M61 -> -511600 | N41: =N68 -> -556168 | O41: =O68 -> -600736 | P41: =P68 -> -689005.5 | Q41: =Q68 -> -689872 | R41: =R68 -> -734440
C45: Supporting Schedule
C49: PPE Schedule
C50: Maintainable Caoex | N50: 3 | O50: 3 | P50: 3 | Q50: 3 | R50: 3
C51: Incremental Capex | N51: 0 | O51: 0 | P51: 0 | Q51: 0 | R51: 0
C55: PPE Schedule
C56: Beginning Balance | N56: =M59 -> 1101595 | O56: =N59 -> 1101595 | P56: =O59 -> 1101595 | Q56: =P59 -> 1188998 | R56: =Q59 -> 1101595
C57: Add: Capex | N57: =(N58*N50)+N51 -> 0 | O57: =(O58*O50)+O51 -> 0 | P57: =(P58*P50)+P51 -> 131104.49 | Q57: =(Q58*Q50)+Q51 -> 0 | R57: =(R58*R50)+R51 -> 0
C58: Less: Depreciation | N58: =N56*N19 -> 0 | O58: =O56*O19 -> 0 | P58: =P56*P19 -> 43701.497 | Q58: =Q56*Q19 -> 0 | R58: =R56*R19 -> 0
C59: Ending Balance | M59: =SOFP!M27 -> 1101595 | N59: =N56+N57-N58 -> 1101595 | O59: =O56+O57-O58 -> 1101595 | P59: =P56+P57-P58 -> 1188998 | Q59: =Q56+Q57-Q58 -> 1101595 | R59: =R56+R57-R58 -> 1101595
C64: Retained Earnings Schedule
C65: Beginning Balance | N65: =M68 -> -511600 | O65: =N68 -> -556168 | P65: =O68 -> -600736 | Q65: =P68 -> -689005.5 | R65: =Q68 -> -689872
C66: Add:Net income | N66: =IS!N31 -> -44568 | O66: =IS!O31 -> -44568 | P66: =IS!P31 -> -88269.497 | Q66: =IS!Q31 -> -44568 | R66: =IS!R31 -> -44568
C67: Less:Dividend paid | N67: =N66*N70 -> 0 | O67: =O66*O70 -> 0 | P67: =P66*P70 -> 0 | Q67: =Q66*Q70 -> 0 | R67: =R66*R70 -> 0
C68: Ending Balance | M68: =SOFP!M46 -> -511600 | N68: =N65+N66-N67 -> -556168 | O68: =O65+O66-O67 -> -600736 | P68: =P65+P66-P67 -> -689005.5 | Q68: =Q65+Q66-Q67 -> -689872 | R68: =R65+R66-R67 -> -734440
C70: Dividend Paid Ratio | I70: ='Historical Data'!I40/'Historical Data'!I31 -> 0 | J70: ='Historical Data'!J40/'Historical Data'!J31 -> 0 | K70: ='Historical Data'!K40/'Historical Data'!K31 -> 0 | L70: ='Historical Data'!L40/'Historical Data'!L31 -> 0 | M70: ='Historical Data'!M40/'Historical Data'!M31 -> 0 | N70: =AVERAGE($I$70:$M$70) -> 0 | O70: =AVERAGE($I$70:$M$70) -> 0 | P70: =AVERAGE($I$70:$M$70) -> 0 | Q70: =AVERAGE($I$70:$M$70) -> 0 | R70: =AVERAGE($I$70:$M$70) -> 0
...

Sheet IS
Q2: MODEL GUIDE
C4: Austin Laz
C5: Start Date | I5: 43466 | J5: 43831 | K5: 44197 | L5: 44562 | M5: 44927 | N5: 45292 | O5: 45658 | P5: 46023 | Q5: 46388 | R5: 46753
C6: End Date | H6: 43465 | I6: 43830 | J6: 44196 | K6: 44561 | L6: 44926 | M6: 45291 | N6: 45657 | O6: 46022 | P6: 46387 | Q6: 46752 | R6: 47118
C7: Years | I7: 2019 | J7: 2020 | K7: 2021 | L7: 2022 | M7: 2023 | N7: 2023 | O7: 2024 | P7: 2025 | Q7: 2026 | R7: 2027
C8: Number of Days | I8: 364 | J8: 364 | K8: 364 | L8: 364 | M8: 364 | N8: 364 | O8: 364 | P8: 364 | Q8: 364 | R8: 364
C13: Description | G13: Unit
I14: N'000 | J14: N'000 | K14: N'000 | L14: N'000 | M14: N'000 | N14: N'000 | O14: N'000 | P14: N'000 | Q14: N'000 | R14: N'000
C15: INCOME STATEMENT
C17: Revenue | I17: ='Historical Data'!I18 -> 205757 | J17: ='Historical Data'!J18 -> 0 | K17: ='Historical Data'!K18 -> 0 | L17: ='Historical Data'!L18 -> 0 | M17: ='Historical Data'!M18 -> 0 | N17: =M17*(1+'Assumptions and Drivers'!N16) -> 0 | O17: =N17*(1+'Assumptions and Drivers'!O16) -> 0 | P17: =O17*(1+'Assumptions and Drivers'!P16) -> 0 | Q17: =P17*(1+'Assumptions and Drivers'!Q16) -> 0 | R17: =Q17*(1+'Assumptions and Drivers'!R16) -> 0
C18: Cost of Sales | I18: ='Historical Data'!I19 -> -236482 | J18: ='Historical Data'!J19 -> 0 | K18: ='Historical Data'!K19 -> 0 | L18: ='Historical Data'!L19 -> 0 | M18: ='Historical Data'!M19 -> 0 | N18: =N17*('Assumptions and Drivers'!N17) -> 0 | O18: =O17*('Assumptions and Drivers'!O17) -> 0 | P18: =P17*('Assumptions and Drivers'!P17) -> 0 | Q18: =Q17*('Assumptions and Drivers'!Q17) -> 0 | R18: =R17*('Assumptions and Drivers'!R17) -> 0
C19: Gross Profit/(Loss) | I19: =I17+I18 -> -30725 | J19: =J17+J18 -> 0 | K19: =K17+K18 -> 0 | L19: =L17+L18 -> 0 | M19: =M17+M18 -> 0 | N19: =N17+N18 -> 0 | O19: =O17+O18 -> 0 | P19: =P17+P18 -> 0 | ... R19: =R17+R18 -> 0
C21: SG&A | I21: ='Historical Data'!I22+'Historical Data'!I23 -> -47121 | J21: ='Historical Data'!J22+'Historical Data'!J23 -> -142139 | K21: ='Historical Data'!K22+'Historical Data'!K23 -> -44568 | L21: ='Historical Data'!L22+'Historical Data'!L23 -> -44568 | M21: ='Historical Data'!M22+'Historical Data'!M23 -> -44568 | N21: =AVERAGE(K21:M21) -> -44568 | O21: =AVERAGE(L21:N21) -> -44568 | P21: =AVERAGE(M21:O21) -> -44568 | Q21: =AVERAGE(N21:P21) -> -44568 | R21: =AVERAGE(O21:Q21) -> -44568
C22: EBITDA | I22: =I19+I21+I24 -> 114468 | J22: =J19+J21+J24 -> 0 | K22: =K19+K21+K24 -> 0 | L22: =L19+L21+L24 -> 0 | M22: =M19+M21+M24 -> -44568 | N22: =N19+N21 -> -44568 | O22: =O19+O21 -> -44568 | P22: =P19+P21 -> -44568 | Q22: =Q19+Q21 -> -44568 | R22: =R19+R21 -> -44568
C24: Depreciation & Ammortization | I24: ='Historical Data'!I39 -> 192314 | J24: ='Historical Data'!J39 -> 142139 | K24: ='Historical Data'!K39 -> 44568 | L24: ='Historical Data'!L39 -> 44568 | M24: ='Historical Data'!M39 -> 0 | N24: ='Assumptions and Drivers'!N58 -> 0 | O24: ='Assumptions and Drivers'!O58 -> 0 | P24: ='Assumptions and Drivers'!P58 -> 43701.497 | Q24: ='Assumptions and Drivers'!Q58 -> 0 | R24: ='Assumptions and Drivers'!R58 -> 0
C25: EBIT | I25: =I22-I24 -> -77846 | J25: =J22-J24 -> -142139 | K25: =K22-K24 -> -44568 | L25: =L22-L24 -> -44568 | M25: =M22-M24 -> -44568 | N25: =N22-N24 -> -44568 | O25: =O22-O24 -> -44568 | P25: =P22-P24 -> -88269.497 | ... R25: =R22-R24 -> -44568
C27: Finance cost-net | I27: ='Historical Data'!I24 -> -6371 | J27: ='Historical Data'!J24 -> 0 | K27: ='Historical Data'!K24 -> 0 | L27: ='Historical Data'!L24 -> 0 | M27: ='Historical Data'!M24 -> 0 | N27: ='Assumptions and Drivers'!N20*IS!N25 -> 0 | O27: ='Assumptions and Drivers'!O20*IS!O25 -> 0 | P27: ='Assumptions and Drivers'!P20*IS!P25 -> 0 | Q27: ='Assumptions and Drivers'!Q20*IS!Q25 -> 0 | R27: ='Assumptions and Drivers'!R20*IS!R25 -> 0
C28: EBT | I28: =I25+I27 -> -84217 | J28: =J25+J27 -> -142139 | K28: =K25+K27 -> -44568 | L28: =L25+L27 -> -44568 | M28: =M25+M27 -> -44568 | N28: =N25-N27 -> -44568 | O28: =O25-O27 -> -44568 | P28: =P25-P27 -> -88269.497 | Q28: =Q25-Q27 -> -44568 | R28: =R25-R27 -> -44568
C30: Tax Expenses | I30: ='Historical Data'!I26 -> -151 | J30: ='Historical Data'!J26 -> 0 | K30: ='Historical Data'!K26 -> 0 | L30: ='Historical Data'!L26 -> 0 | M30: ='Historical Data'!M26 -> 0 | N30: ='Assumptions and Drivers'!N21 -> 0 | O30: ='Assumptions and Drivers'!O21 -> 0 | P30: ='Assumptions and Drivers'!P21 -> 0 | Q30: ='Assumptions and Drivers'!Q21 -> 0 | R30: ='Assumptions and Drivers'!R21 -> 0
C31: Net income | I31: =I28+I30 -> -84368 | J31: =J28+J30 -> -142139 | K31: =K28+K30 -> -44568 | L31: =L28+L30 -> -44568 | M31: =M28+M30 -> -44568 | N31: =N28-N30 -> -44568 | O31: =O28-O30 -> -44568 | P31: =P28-P30 -> -88269.497 | Q31: =Q28-Q30 -> -44568 | R31: =R28-R30 -> -44568

Sheet SOFP
B3: Check | I3: =IF(I30=I48, "Good", "Error") -> Good | J3: =IF(J30=J48, "Good", "Error") -> Good | K3: =IF(K30=K48, "Good", "Error") -> Good | L3: =IF(L30=L48, "Good", "Error") -> Good | M3: =IF(M30=M48, "Good", "Error") -> Good | N3: =IF(N30=N48, "Good", "Error") -> Good | O3: =IF(O30=O48, "Good", "Error") -> Good | P3: =IF(P30=P48, "Good", "Error") -> Good | ... R3: =IF(R30=R48, "Good", "Error") -> Good
B4: Reconciliation Tool | I4: =I30-I48 -> 0 | J4: =J30-J48 -> 0 | K4: =K30-K48 -> 0 | L4: =L30-L48 -> 0 | M4: =M30-M48 -> 0 | N4: =N30-N48 -> 0 | O4: =O30-O48 -> 0 | P4: =P30-P48 -> 0 | ... R4: =R30-R48 -> 0
Q5: MODEL GUIDE
C7: Austin Laz
C8: Start Date | I8: 43466 | J8: 43831 | K8: 44197 | L8: 44562 | M8: 44927 | N8: 45292 | O8: 45658 | P8: 46023 | Q8: 46388 | R8: 46753
C9: End Date | H9: 43465 | I9: 43830 | J9: 44196 | K9: 44561 | L9: 44926 | M9: 45291 | N9: 45657 | O9: 46022 | P9: 46387 | Q9: 46752 | R9: 47118
C10: Years | I10: 2019 | J10: 2020 | K10: 2021 | L10: 2022 | M10: 2023 | N10: 2023 | O10: 2024 | P10: 2025 | Q10: 2026 | R10: 2027
C11: Number of Days | I11: 365 | J11: 365 | K11: 365 | L11: 365 | M11: 365 | N11: 365 | O11: 365 | P11: 365 | Q11: 365 | R11: 365
C16: Description | G16: Unit
C18: STATEMENT OF FINANCIAL POSITION
C20: Current Asset
C21: Cash and Cash Equivalent | I21: ='Historical Data'!I54 -> 1057 | J21: ='Historical Data'!J54 -> 1057 | K21: ='Historical Data'!K54 -> 1057 | L21: ='Historical Data'!L54 -> 1057 | M21: ='Historical Data'!M54 -> 1057 | N21: =SOCF!N40 -> -43513 | O21: =SOCF!O40 -> -88081.4 | P21: =SOCF!P40 -> -263754.17 | Q21: =SOCF!Q40 -> -43513 | R21: =SOCF!R40 -> -43513
C22: Inventories | I22: ='Historical Data'!I52 -> 25830 | J22: ='Historical Data'!J52 -> 25830 | K22: ='Historical Data'!K52 -> 25830 | L22: ='Historical Data'!L52 -> 25830 | M22: ='Historical Data'!M52 -> 25830 | N22: ='Assumptions and Drivers'!N28 -> 25832 | O22: ='Assumptions and Drivers'!O28 -> 25832.4 | P22: ='Assumptions and Drivers'!P28 -> 25832.68 | Q22: ='Assumptions and Drivers'!Q28 -> 25832.816 | R22: ='Assumptions and Drivers'!R28 -> 25832.779
C23: Trade receivables | I23: ='Historical Data'!I53 -> 22261 | J23: ='Historical Data'!J53 -> 22261 | K23: ='Historical Data'!K53 -> 22261 | L23: ='Historical Data'!L53 -> 22261 | M23: ='Historical Data'!M53 -> 22261 | N23: ='Assumptions and Drivers'!N29 -> 22261 | O23: ='Assumptions and Drivers'!O29 -> 22261 | P23: ='Assumptions and Drivers'!P29 -> 22261 | Q23: ='Assumptions and Drivers'!Q29 -> 22261 | R23: ='Assumptions and Drivers'!R29 -> 22261
C24: Total current Asset | I24: =SUM(I21:I23) -> 49148 | J24: =SUM(J21:J23) -> 49148 | K24: =SUM(K21:K23) -> 49148 | L24: =SUM(L21:L23) -> 49148 | M24: =SUM(M21:M23) -> 49148 | N24: =N22+N23+N21 -> 4580 | O24: =O22+O23+O21 -> -39988 | P24: =P22+P23+P21 -> -215660.49 | Q24: =Q22+Q23+Q21 -> 48093.816 | R24: =R22+R23+R21 -> 48093.779
C26: Non Current Assets
C27: PPE | I27: ='Historical Data'!I48 -> 1332870 | J27: ='Historical Data'!J48 -> 1190731 | K27: ='Historical Data'!K48 -> 1146163 | L27: ='Historical Data'!L48 -> 1101595 | M27: ='Historical Data'!M48 -> 1101595 | N27: ='Assumptions and Drivers'!N31 -> 1101595 | O27: ='Assumptions and Drivers'!O31 -> 1101595 | P27: ='Assumptions and Drivers'!P31 -> 1188998 | Q27: ='Assumptions and Drivers'!Q31 -> 1101595 | R27: ='Assumptions and Drivers'!R31 -> 1101595
C28: Intangible | I28: ='Historical Data'!I49 -> 151835 | J28: ='Historical Data'!J49 -> 151835 | K28: ='Historical Data'!K49 -> 151835 | L28: ='Historical Data'!L49 -> 151835 | M28: ='Historical Data'!M49 -> 151835 | N28: ='Assumptions and Drivers'!N32 -> 151835 | O28: ='Assumptions and Drivers'!O32 -> 151835 | P28: ='Assumptions and Drivers'!P32 -> 151835 | Q28: ='Assumptions and Drivers'!Q32 -> 151835 | R28: ='Assumptions and Drivers'!R32 -> 151835
C29: Total Non-current Asset | I29: =SUM(I27:I28) -> 1484705 | J29: =SUM(J27:J28) -> 1342566 | K29: =SUM(K27:K28) -> 1297998 | L29: =SUM(L27:L28) -> 1253430 | M29: =SUM(M27:M28) -> 1253430 | N29: =N27+N28 -> 1253430 | O29: =O27+O28 -> 1253430 | P29: =P27+P28 -> 1340833 | Q29: =Q27+Q28 -> 1253430 | R29: =R27+R28 -> 1253430
C30: Total Assets | I30: =I24+I29 -> 1533853 | J30: =J24+J29 -> 1391714 | K30: =K24+K29 -> 1347146 | L30: =L24+L29 -> 1302578 | M30: =M24+M29 -> 1302578 | N30: =N24+N29 -> 1258010 | O30: =O24+O29 -> 1213442 | P30: =P24+P29 -> 1125172.5 | ... R30: =R24+R29 -> 1301523
C33: Current Liability
C34: Trade payables | I34: ='Historical Data'!I67 -> 1857 | J34: ='Historical Data'!J67 -> 1857 | K34: ='Historical Data'!K67 -> 1857 | L34: ='Historical Data'!L67 -> 1857 | M34: ='Historical Data'!M67 -> 1857 | N34: ='Assumptions and Drivers'!N34 -> 1857 | O34: ='Assumptions and Drivers'!O34 -> 1857 | P34: ='Assumptions and Drivers'!P34 -> 1857 | Q34: ='Assumptions and Drivers'!Q34 -> 1857 | R34: ='Assumptions and Drivers'!R34 -> 1857
C35: Other payables | I35: ='Historical Data'!I68 -> 4971 | J35: ='Historical Data'!J68 -> 4971 | K35: ='Historical Data'!K68 -> 4971 | L35: ='Historical Data'!L68 -> 4971 | M35: ='Historical Data'!M68 -> 4971 | N35: ='Assumptions and Drivers'!N35 -> 4971 | O35: ='Assumptions and Drivers'!O35 -> 4971 | P35: ='Assumptions and Drivers'!P35 -> 4971 | Q35: ='Assumptions and Drivers'!Q35 -> 4971 | R35: ='Assumptions and Drivers'!R35 -> 4971
C36: Total Current Liability | I36: =I34+I35 -> 6828 | J36: =J34+J35 -> 6828 | K36: =K34+K35 -> 6828 | L36: =L34+L35 -> 6828 | M36: =M34+M35 -> 6828 | N36: =N34+N35 -> 6828 | O36: =O34+O35 -> 6828 | P36: =P34+P35 -> 6828 | ... R36: =R34+R35 -> 6828
C38: Non current Liability
C39: Long term borrowing | I39: ='Historical Data'!I65 -> 42644 | J39: ='Historical Data'!J65 -> 42644 | K39: ='Historical Data'!K65 -> 42644 | L39: ='Historical Data'!L65 -> 42644 | M39: ='Historical Data'!M65 -> 42644 | N39: ='Assumptions and Drivers'!N37 -> 42644 | O39: ='Assumptions and Drivers'!O37 -> 42644 | P39: ='Assumptions and Drivers'!P37 -> 42644 | Q39: ='Assumptions and Drivers'!Q37 -> 42644 | R39: ='Assumptions and Drivers'!R37 -> 42644
C40: Total Non-current Liability | I40: =I39 -> 42644 | J40: =J39 -> 42644 | K40: =K39 -> 42644 | L40: =L39 -> 42644 | M40: =M39 -> 42644 | N40: =N39 -> 42644 | O40: =O39 -> 42644 | P40: =P39 -> 42644 | ... R40: =R39 -> 42644
C41: Total Liability | I41: =I40+I36 -> 49472 | J41: =J40+J36 -> 49472 | K41: =K40+K36 -> 49472 | L41: =L40+L36 -> 49472 | M41: =M40+M36 -> 49472 | N41: =N36+N40 -> 49472 | O41: =O36+O40 -> 49472 | P41: =P36+P40 -> 49472 | Q41: =Q36+Q40 -> 49472 | R41: =R36+R40 -> 49472
C43: Shareholders Equity
C44: Paid up share capital | I44: ='Historical Data'!I59 -> 539930 | J44: ='Historical Data'!J59 -> 539930 | K44: ='Historical Data'!K59 -> 539930 | L44: ='Historical Data'!L59 -> 539930 | M44: ='Historical Data'!M59 -> 539930 | N44: ='Assumptions and Drivers'!N39 -> 539930 | O44: ='Assumptions and Drivers'!O39 -> 539930 | P44: ='Assumptions and Drivers'!P39 -> 539930 | Q44: ='Assumptions and Drivers'!Q39 -> 539930 | R44: ='Assumptions and Drivers'!R39 -> 539930
C45: Capital Reserves | I45: ='Historical Data'!I60 -> 1224776 | J45: ='Historical Data'!J60 -> 1224776 | K45: ='Historical Data'!K60 -> 1224776 | L45: ='Historical Data'!L60 -> 1224776 | M45: ='Historical Data'!M60 -> 1224776 | N45: ='Assumptions and Drivers'!N40 -> 1224776 | O45: ='Assumptions and Drivers'!O40 -> 1224776 | P45: ='Assumptions and Drivers'!P40 -> 1224776 | Q45: ='Assumptions and Drivers'!Q40 -> 1224776 | R45: ='Assumptions and Drivers'!R40 -> 1224776
C46: Retained Earnings | I46: ='Historical Data'!I61 -> -280325 | J46: ='Historical Data'!J61 -> -422464 | K46: ='Historical Data'!K61 -> -467032 | L46: ='Historical Data'!L61 -> -511600 | M46: ='Historical Data'!M61 -> -511600 | N46: ='Assumptions and Drivers'!N41 -> -556168 | O46: ='Assumptions and Drivers'!O41 -> -600736 | P46: ='Assumptions and Drivers'!P41 -> -689005.5 | Q46: ='Assumptions and Drivers'!Q41 -> -689872 | R46: ='Assumptions and Drivers'!R41 -> -734440
C47: Total shareholders equity | I47: =I44+I45+I46 -> 1484381 | J47: =J44+J45+J46 -> 1342242 | K47: =K44+K45+K46 -> 1297674 | L47: =L44+L45+L46 -> 1253106 | M47: =M44+M45+M46 -> 1253106 | N47: =N44+N45+N46 -> 1208538 | O47: =O44+O45+O46 -> 1163970 | P47: =P44+P45+P46 -> 1075700.5 | ... R47: =R44+R45+R46 -> 1030266
C48: Total shareholders equity and Liabilities | I48: =I47+I41 -> 1533853 | J48: =J47+J41 -> 1391714 | K48: =K47+K41 -> 1347146 | L48: =L47+L41 -> 1302578 | M48: =M47+M41 -> 1302578 | N48: =N47+N41 -> 1258010 | O48: =O47+O41 -> 1213442 | P48: =P47+P41 -> 1125172.5 | ... R48: =R47+R41 -> 1079738

Sheet SOCF
Q2: MODEL GUIDE
C4: Austin Laz
C5: Start Date | I5: 43466 | J5: 43831 | K5: 44197 | L5: 44562 | M5: 44927 | N5: 45292 | O5: 45658 | P5: 46023 | Q5: 46388 | R5: 46753
C6: End Date | H6: 43465 | I6: 43830 | J6: 44196 | K6: 44561 | L6: 44926 | M6: 45291 | N6: 45657 | O6: 46022 | P6: 46387 | Q6: 46752 | R6: 47118
C7: Years | I7: 2019 | J7: 2020 | K7: 2021 | L7: 2022 | M7: 2023 | N7: 2023 | O7: 2024 | P7: 2025 | Q7: 2026 | R7: 2027
C8: Number of Days | I8: 365 | J8: 365 | K8: 365 | L8: 365 | M8: 365 | N8: 365 | O8: 365 | P8: 365 | Q8: 365 | R8: 365
C13: Description | G13: Unit
C16: Cash from Operating Activities
C17: EBIT/Operating Income | N17: =IS!N25 -> -44568 | O17: =IS!O25 -> -44568 | P17: =IS!P25 -> -88269.497 | Q17: =IS!Q25 -> -44568 | R17: =IS!R25 -> -44568
C18: Add:Depreciation | N18: =IS!N24 -> 0 | O18: =IS!O24 -> 0 | P18: =IS!P24 -> 43701.497 | Q18: =IS!Q24 -> 0 | R18: =IS!R24 -> 0
C19: Finance cost-net | N19: =IS!N27 -> 0 | O19: =IS!O27 -> 0 | P19: =IS!P27 -> 0 | Q19: =IS!Q27 -> 0 | R19: =IS!R27 -> 0
C20: Tax Expense | N20: =IS!N30 -> 0 | O20: =IS!O30 -> 0 | P20: =IS!P30 -> 0 | Q20: =IS!Q30 -> 0 | R20: =IS!R30 -> 0
C21: Change in OWC | N21: ='Assumptions and Drivers'!N86 -> -2 | O21: ='Assumptions and Drivers'!O86 -> -0.4 | P21: ='Assumptions and Drivers'!P86 -> -0.28 | Q21: ='Assumptions and Drivers'!Q86 -> -0.136 | R21: ='Assumptions and Drivers'!R86 -> 0.0368
C22: Cash from operation | N22: =SUM(N17:N21) -> -44570 | O22: =SUM(O17:O21) -> -44568.4 | P22: =SUM(P17:P21) -> -44568.28 | Q22: =SUM(Q17:Q21) -> -79005 | R22: =SUM(R17:R21) -> -79005
C24: Cash from investing activities
C25: Capex | N25: ='Assumptions and Drivers'!N57 -> 0 | O25: ='Assumptions and Drivers'!O57 -> 0 | P25: =-'Assumptions and Drivers'!P57 -> -131104.49 | Q25: ='Assumptions and Drivers'!Q57 -> 0 | R25: ='Assumptions and Drivers'!R57 -> 0
C26: Cash from investing | N26: =SUM(N25) -> 0 | O26: =SUM(O25) -> 0 | P26: =SUM(P25) -> -131104.49 | Q26: =SUM(Q25) -> 0 | R26: =SUM(R25) -> 0
C28: Cash from financing activities
C29: Changes in Paid up share capital | N29: ='Assumptions and Drivers'!M88 -> 0 | O29: ='Assumptions and Drivers'!N88 -> 0 | P29: ='Assumptions and Drivers'!O88 -> 0 | Q29: ='Assumptions and Drivers'!P88 -> 0 | R29: ='Assumptions and Drivers'!Q88 -> 0
C30: Changes in Capital Reserves | N30: ='Assumptions and Drivers'!M89 -> 0 | O30: ='Assumptions and Drivers'!N89 -> 0 | P30: ='Assumptions and Drivers'!O89 -> 0 | Q30: ='Assumptions and Drivers'!P89 -> 0 | R30: ='Assumptions and Drivers'!Q89 -> 0
C31: Dividend paid | N31: ='Assumptions and Drivers'!M67 -> 0 | O31: ='Assumptions and Drivers'!N67 -> 0 | P31: ='Assumptions and Drivers'!O67 -> 0 | Q31: ='Assumptions and Drivers'!P67 -> 0 | R31: ='Assumptions and Drivers'!Q67 -> 0
C32: Loan repayment | N32: ='Assumptions and Drivers'!M91 -> 0 | O32: ='Assumptions and Drivers'!N91 -> 0 | P32: ='Assumptions and Drivers'!O91 -> 0 | Q32: ='Assumptions and Drivers'!P91 -> 0 | R32: ='Assumptions and Drivers'!Q91 -> 0
C33: Cash from financing | N33: =SUM(N29:N32) -> 0 | O33: =SUM(O29:O32) -> 0 | P33: =SUM(P29:P32) -> 0 | Q33: =SUM(Q29:Q32) -> 0 | R33: =SUM(R29:R32) -> 0
C35: Cash during the period | N35: =N33+N26+N22 -> -44570 | O35: =O33+O26+O22 -> -44568.4 | P35: =P33+P26+P22 -> -175672.77 | Q35: =Q33+Q26+Q22 -> -44568.4 | R35: =R33+R26+R22 -> -44568.4
C37: Cash schedule
C38: Beginning balance | N38: =M40 -> 1057 | O38: =N40 -> -43513 | P38: =O40 -> -88081.4 | Q38: =P40 -> -263754.17 | R38: =Q40 -> 1057
C39: Cash during period | N39: =N35 -> -44570 | O39: =O35 -> -44568.4 | P39: =P35 -> -175672.77 | Q39: =Q35 -> -44570 | R39: =R35 -> -44570
C40: Ending balance | M40: =SOFP!M21 -> 1057 | N40: =SUM(N38:N39) -> -43513 | O40: =SUM(O38:O39) -> -88081.4 | P40: =SUM(P38:P39) -> -263754.17 | Q40: =SUM(Q38:Q39) -> -43513 | R40: =SUM(R38:R39) -> -43513

Sheet Charts and Graphs 
D3: Profitability
D18: Efficiency
D34: Liquidity
D49: Solvency

Sheet Financial Analysis
R4: MODEL GUIDE
D6: Austin Laz
D7: Start Date | J7: 43466 | K7: 43831 | L7: 44197 | M7: 44562 | N7: 44927 | O7: 45292 | P7: 45658 | Q7: 46023 | R7: 46388 | S7: 46753
D8: End Date | I8: 43465 | J8: 43830 | K8: 44196 | L8: 44561 | M8: 44926 | N8: 45291 | O8: 45657 | P8: 46022 | Q8: 46387 | R8: 46752 | S8: 47118
D9: Years | J9: 2019 | K9: 2020 | L9: 2021 | M9: 2022 | N9: 2023 | O9: 2023 | P9: 2024 | Q9: 2025 | R9: 2026 | S9: 2027
D10: Number of Days | J10: 364 | K10: 364 | L10: 364 | M10: 364 | N10: 364 | O10: 364 | P10: 364 | Q10: 364 | R10: 364 | S10: 364
D15: Description | H15: Unit
D18: Efficiency Ratio
D19: Days of Sales Outstanding (DSO) | J19: =SOFP!I23/IS!I17*IS!I8 -> 39.381426 | K19: 0 | L19: 0 | M19: 0 | N19: 0 | O19: =AVERAGE(K19:N19) -> 0 | P19: =AVERAGE(K19:O19) -> 0 | Q19: =AVERAGE(L19:P19) -> 0 | R19: =AVERAGE(M19:Q19) -> 0 | S19: =AVERAGE(N19:R19) -> 0
D20: Days of Inventory Outstanding (DIO) | J20: =-(SOFP!I22/IS!I18*IS!I8) -> 39.75829 | K20: 0 | L20: 0 | M20: 0 | N20: 0 | O20: =AVERAGE(K20:N20) -> 0 | P20: =AVERAGE(K20:O20) -> 0 | Q20: =AVERAGE(L20:P20) -> 0 | R20: =AVERAGE(M20:Q20) -> 0 | S20: =AVERAGE(N20:R20) -> 0
D21: Days of Payables Outstanding (DPO) | J21: =-(SOFP!I34/IS!I18*IS!I8) -> 2.8583486 | K21: 0 | L21: 0 | M21: 0 | N21: 0 | O21: =AVERAGE(K21:N21) -> 0 | P21: =AVERAGE(K21:O21) -> 0 | Q21: =AVERAGE(L21:P21) -> 0 | R21: =AVERAGE(M21:Q21) -> 0 | S21: =AVERAGE(N21:R21) -> 0
D22: Operating Cycle | J22: =J19+J20 -> 79.139716 | K22: 0 | L22: 0 | M22: 0 | N22: 0 | O22: =AVERAGE(K22:N22) -> 0 | P22: =AVERAGE(K22:O22) -> 0 | Q22: =AVERAGE(L22:P22) -> 0 | R22: =AVERAGE(M22:Q22) -> 0 | S22: =AVERAGE(N22:R22) -> 0
D23: Cash Conversion Ratio | J23: =J22-J21 -> 76.281367 | K23: 0 | L23: 0 | M23: 0 | N23: 0 | O23: =AVERAGE(K23:N23) -> 0 | P23: =AVERAGE(K23:O23) -> 0 | Q23: =AVERAGE(L23:P23) -> 0 | R23: =AVERAGE(M23:Q23) -> 0 | S23: =AVERAGE(N23:R23) -> 0
D26: Profitability Ratio
D27: Gross Margin | J27: =-(IS!I19/IS!I17) -> 0.14932663 | K27: 0 | L27: 0 | M27: 0 | N27: 0 | O27: =AVERAGE($K27:$N27) -> 0 | P27: =AVERAGE($K27:$N27) -> 0 | Q27: =AVERAGE($K27:$N27) -> 0 | R27: =AVERAGE($K27:$N27) -> 0 | S27: =AVERAGE($K27:$N27) -> 0
D28: Operating Profit Margin | J28: =-(IS!I25/IS!I17) -> 0.3783395 | K28: 0 | L28: 0 | M28: 0 | N28: 0 | O28: =AVERAGE($K28:$N28) -> 0 | P28: =AVERAGE($K28:$N28) -> 0 | Q28: =AVERAGE($K28:$N28) -> 0 | R28: =AVERAGE($K28:$N28) -> 0 | S28: =AVERAGE($K28:$N28) -> 0
D29: Net Income Margin | J29: =-(IS!I31/IS!I17) -> 0.41003708 | K29: 0 | L29: 0 | M29: 0 | N29: 0 | O29: =AVERAGE($K29:$N29) -> 0 | P29: =AVERAGE($K29:$N29) -> 0 | Q29: =AVERAGE($K29:$N29) -> 0 | R29: =AVERAGE($K29:$N29) -> 0 | S29: =AVERAGE($K29:$N29) -> 0
D30: Return on Assets (ROA) | J30: =-(IS!I25/SOFP!I30) -> 0.05075193 | K30: =(IS!J25/SOFP!J30) -> -0.10213233 | L30: =(IS!K25/SOFP!K30) -> -0.033083274 | M30: =(IS!L25/SOFP!L30) -> -0.034215225 | N30: =(IS!M25/SOFP!M30) -> -0.034215225 | O30: =AVERAGE($J30:$N30) -> -0.030578826 | P30: =AVERAGE($J30:$N30) -> -0.030578826 | Q30: =AVERAGE($J30:$N30) -> -0.030578826 | R30: =AVERAGE($J30:$N30) -> -0.030578826 | S30: =AVERAGE($J30:$N30) -> -0.030578826
D31: Return on Equities (ROE) | J31: =-(IS!I31/SOFP!I47) -> 0.05683716 | K31: =(IS!J31/SOFP!J47) -> -0.1058967 | L31: =(IS!K31/SOFP!K47) -> -0.034344527 | M31: =(IS!L31/SOFP!L47) -> -0.035566026 | N31: =(IS!M31/SOFP!M47) -> -0.035566026 | O31: =AVERAGE($J31:$N31) -> -0.030907224 | P31: =AVERAGE($J31:$N31) -> -0.030907224 | Q31: =AVERAGE($J31:$N31) -> -0.030907224 | R31: =AVERAGE($J31:$N31) -> -0.030907224 | S31: =AVERAGE($J31:$N31) -> -0.030907224
D33: Liquidity Ratio
D34: Cash Ratio | J34: =SOFP!I21/SOFP!I36 -> 0.15480375 | K34: =SOFP!J21/SOFP!J36 -> 0.15480375 | L34: =SOFP!K21/SOFP!K36 -> 0.15480375 | M34: =SOFP!L21/SOFP!L36 -> 0.15480375 | N34: =SOFP!M21/SOFP!M36 -> 0.15480375 | O34: =AVERAGE($J34:$N34) -> 0.15480375 | P34: =AVERAGE($J34:$N34) -> 0.15480375 | Q34: =AVERAGE($J34:$N34) -> 0.15480375 | R34: =AVERAGE($J34:$N34) -> 0.15480375 | S34: =AVERAGE($J34:$N34) -> 0.15480375
D35: Quick Ratio | J35: =(SOFP!I24-SOFP!I22)/SOFP!I36 -> 3.4150557 | K35: =(SOFP!J24-SOFP!J22)/SOFP!J36 -> 3.4150557 | L35: =(SOFP!K24-SOFP!K22)/SOFP!K36 -> 3.4150557 | M35: =(SOFP!L24-SOFP!L22)/SOFP!L36 -> 3.4150557 | N35: =(SOFP!M24-SOFP!M22)/SOFP!M36 -> 3.4150557 | O35: =AVERAGE($J35:$N35) -> 3.4150557 | P35: =AVERAGE($J35:$N35) -> 3.4150557 | Q35: =AVERAGE($J35:$N35) -> 3.4150557 | R35: =AVERAGE($J35:$N35) -> 3.4150557 | S35: =AVERAGE($J35:$N35) -> 3.4150557
D36: Current Ratio | J36: =SOFP!I24/SOFP!I36 -> 7.1980082 | K36: =SOFP!J24/SOFP!J36 -> 7.1980082 | L36: =SOFP!K24/SOFP!K36 -> 7.1980082 | M36: =SOFP!L24/SOFP!L36 -> 7.1980082 | N36: =SOFP!M24/SOFP!M36 -> 7.1980082 | O36: =AVERAGE($J36:$N36) -> 7.1980082 | P36: =AVERAGE($J36:$N36) -> 7.1980082 | Q36: =AVERAGE($J36:$N36) -> 7.1980082 | R36: =AVERAGE($J36:$N36) -> 7.1980082 | S36: =AVERAGE($J36:$N36) -> 7.1980082
D38: Solvency Ratios
D39: Debt to Equities | J39: =SOFP!I39/SOFP!I47 -> 0.028728473 | K39: =SOFP!J39/SOFP!J47 -> 0.031770724 | L39: =SOFP!K39/SOFP!K47 -> 0.032861874 | M39: =SOFP!L39/SOFP!L47 -> 0.034030641 | N39: =SOFP!M39/SOFP!M47 -> 0.034030641 | O39: =AVERAGE($J39:$N39) -> 0.032284471 | P39: =AVERAGE($J39:$N39) -> 0.032284471 | Q39: =AVERAGE($J39:$N39) -> 0.032284471 | R39: =AVERAGE($J39:$N39) -> 0.032284471 | S39: =AVERAGE($J39:$N39) -> 0.032284471
D40: Debt to Capital Employed ratio | J40: =SOFP!I39/(SOFP!I30-SOFP!I36) -> 0.027926196 | K40: =SOFP!J39/(SOFP!J30-SOFP!J36) -> 0.030792426 | L40: =SOFP!K39/(SOFP!K30-SOFP!K36) -> 0.03181633 | M40: =SOFP!L39/(SOFP!L30-SOFP!L36) -> 0.032910669 | N40: =SOFP!M39/(SOFP!M30-SOFP!M36) -> 0.032910669 | O40: =AVERAGE($J40:$N40) -> 0.031271258 | P40: =AVERAGE($J40:$N40) -> 0.031271258 | Q40: =AVERAGE($J40:$N40) -> 0.031271258 | R40: =AVERAGE($J40:$N40) -> 0.031271258 | S40: =AVERAGE($J40:$N40) -> 0.031271258
D41: Intrest Coverage Ratios | J41: =-(IS!I27/SOFP!I39) -> 0.14939968 | K41: =-(IS!J27/SOFP!J39) -> 0 | L41: =-(IS!K27/SOFP!K39) -> 0 | M41: =-(IS!L27/SOFP!L39) -> 0 | N41: =-(IS!M27/SOFP!M39) -> 0 | O41: =AVERAGE(K41:N41) -> 0 | P41: =AVERAGE(L41:O41) -> 0 | Q41: =AVERAGE(M41:P41) -> 0 | R41: =AVERAGE(N41:Q41) -> 0 | S41: =AVERAGE(O41:R41) -> 0

Sheet Valuation
G7: Austin Laz
G8: Start Date | M8: 43466 | N8: 43831 | O8: 44197 | P8: 44562 | Q8: 44927 | R8: 45292 | S8: 45658 | T8: 46023 | U8: 46388 | V8: 46753
G9: End Date | L9: 43465 | M9: 43830 | N9: 44196 | O9: 44561 | P9: 44926 | Q9: 45291 | R9: 45657 | S9: 46022 | T9: 46387 | U9: 46752 | V9: 47118
G10: Years | M10: 2019 | N10: 2020 | O10: 2021 | P10: 2022 | Q10: 2023 | R10: 2023 | S10: 2024 | T10: 2025 | U10: 2026 | V10: 2027
G11: Number of Days | M11: 364 | N11: 364 | O11: 364 | P11: 364 | Q11: 364 | R11: 364 | S11: 364 | T11: 364 | U11: 364 | V11: 364
F17: Valuation Date
F19: CAPM/Cost of equity
F20: Risk free rate | I20: [%] | K20: 0.168
F21: Beta | I21: [Number] | K21: 0.98
F22: Equity Risk Premium | I22: [%] | K22: 0.05
F23: Cost of Equity | I23: [%] | K23: =K20+(K21*K22) -> 0.217
F25: Cost of Debt
F26: Maximum Lending Rate | I26: [%] | K26: 0.32
F27: Statutory Tax Rate | I27: [%] | K27: 0.27
F28: Cost of Debt | I28: [%] | K28: =K26*(1-K27) -> 0.2336
F30: Weight
F31: Debt (wd) | I31: [%] | K31: =SOFP!I39/SOFP!I47 -> 0.028728473
F32: Equity (wd) | I32: [%] | K32: =(1-K31) -> 0.97127153
F34: WACC | I34: [%] | K34: =(K23*K32)+(K28*K31) -> 0.21747689
F36: Terminal growth rate | K36: 0.02
F37: Shares Outstanding | K37: 1079860
F38: Current Share Price | K38: 4.08
F39: Market Capitalization | K39: 4405828.8
I41: DCF Valuation
I42: EBIT | R42: =IS!N25 -> -44568 | S42: =IS!O25 -> -44568 | T42: =IS!P25 -> -88269.497 | U42: =IS!Q25 -> -44568 | V42: =IS!R25 -> -44568
I43: Less: Tax expense | R43: =IS!N30 -> 0 | S43: =IS!O30 -> 0 | T43: =IS!P30 -> 0 | U43: =IS!Q30 -> 0 | V43: =IS!R30 -> 0
I44: NOPAT | R44: =R42+R43 -> -44568 | S44: =S42+S43 -> -44568 | T44: =T42+T43 -> -88269.497 | U44: =U42+U43 -> -44568 | V44: =V42+V43 -> -44568
I45: Add:Depreciation | R45: =SOCF!N18 -> 0 | S45: =SOCF!O18 -> 0 | T45: =SOCF!P18 -> 43701.497 | U45: =SOCF!Q18 -> 0 | V45: =SOCF!R18 -> 0
I46: Add: Changes in OWC | R46: ='Assumptions and Drivers'!N86 -> -2 | S46: ='Assumptions and Drivers'!O86 -> -0.4 | T46: ='Assumptions and Drivers'!P86 -> -0.28 | U46: ='Assumptions and Drivers'!Q86 -> -0.136 | V46: ='Assumptions and Drivers'!R86 -> 0.0368
I47: Less: Capex | R47: =SOCF!N25 -> 0 | S47: =SOCF!O25 -> 0 | T47: =SOCF!P25 -> -131104.49 | U47: =SOCF!Q25 -> 0 | V47: =SOCF!R25 -> 0
I48: FCFF | R48: =R44+R45+R46-R47 -> -44570 | S48: =S44+S45+S46-S47 -> -44568.4 | T48: =T44+T45+T46-T47 -> 86536.212 | U48: =U44+U45+U46-U47 -> -44570 | V48: =V44+V45+V46-V47 -> -44570
I51: Period Count | R51: 1 | S51: 2 | T51: 3 | U51: 4 | V51: 5
I52: Discount Factor | R52: =(1+$K$34)^-R51 -> 0.82137083 | S52: =(1+$K$34)^-S51 -> 0.67465003 | T52: =(1+$K$34)^-T51 -> 0.55413785 | U52: =(1+$K$34)^-U51 -> 0.45515267 | V52: =(1+$K$34)^-V51 -> 0.37384912
I53: Present Value | R53: =R48*R52 -> -36608.498 | S53: =S48*S52 -> -30068.073 | T53: =T48*T52 -> 47952.991 | U53: =U48*U52 -> -36608.498 | V53: =V48*V52 -> -36608.498
G58: NPV of FCFF | K58: =SUM(R53:V53) -> 0
G61: Terminal Value
G62: FCFF | K62: =V48 -> 0
G63: Growth Rate | K63: =K36 -> 0.02
G64: WACC | K64: =K34 -> 0.21747689
G65: Terminal Value | K65: =(K62*(1+K63))/(K64-K63) -> 0
...

Sheet Personal Notes
C8: Forcastin BS
